Workbook

Sheet Sheet1
A1: Year | B1: Scenarios | C1: Food production（Mt）
A2: =[1]历史产量!A290 -> 2020 | B2: Historical | C2: =[1]历史产量!D290 -> 606.7786
A3: =[1]历史产量!A322 -> 2021 | B3: Historical | C3: =[1]历史产量!D322 -> 622.3377
A4: =[1]历史产量!A354 -> 2022 | B4: Historical | C4: =[1]历史产量!D354 -> 623.4213
A5: =[1]历史产量!A386 -> 2023 | B5: Historical | C5: =[1]历史产量!D386 -> 632.0354
A6: =[1]历史产量!A418 -> 2024 | B6: Historical | C6: =[1]历史产量!D418 -> 642.5509
A7: =[1]未来产量!A2 -> 2025 | B7: =[1]未来产量!B2 -> SSP1 | C7: =[1]未来产量!E2 -> 650.348
A8: =[1]未来产量!A34 -> 2025 | B8: =[1]未来产量!B34 -> SSP2 | C8: =[1]未来产量!E34 -> 650.348
A9: =[1]未来产量!A66 -> 2025 | B9: =[1]未来产量!B66 -> SSP3 | C9: =[1]未来产量!E66 -> 650.348
A10: =[1]未来产量!A98 -> 2025 | B10: =[1]未来产量!B98 -> SSP4 | C10: =[1]未来产量!E98 -> 650.348
A11: =[1]未来产量!A130 -> 2025 | B11: =[1]未来产量!B130 -> SSP5 | C11: =[1]未来产量!E130 -> 650.348
A12: =[1]未来产量!A162 -> 2026 | B12: =[1]未来产量!B162 -> SSP1 | C12: =[1]未来产量!E162 -> 650.06505
A13: =[1]未来产量!A194 -> 2026 | B13: =[1]未来产量!B194 -> SSP2 | C13: =[1]未来产量!E194 -> 652.92337
A14: =[1]未来产量!A226 -> 2026 | B14: =[1]未来产量!B226 -> SSP3 | C14: =[1]未来产量!E226 -> 654.44395
A15: =[1]未来产量!A258 -> 2026 | B15: =[1]未来产量!B258 -> SSP4 | C15: =[1]未来产量!E258 -> 650.51685
A16: =[1]未来产量!A290 -> 2026 | B16: =[1]未来产量!B290 -> SSP5 | C16: =[1]未来产量!E290 -> 652.59469
A17: =[1]未来产量!A322 -> 2027 | B17: =[1]未来产量!B322 -> SSP1 | C17: =[1]未来产量!E322 -> 649.78211
A18: =[1]未来产量!A354 -> 2027 | B18: =[1]未来产量!B354 -> SSP2 | C18: =[1]未来产量!E354 -> 655.49874
A19: =[1]未来产量!A386 -> 2027 | B19: =[1]未来产量!B386 -> SSP3 | C19: =[1]未来产量!E386 -> 658.53989
A20: =[1]未来产量!A418 -> 2027 | B20: =[1]未来产量!B418 -> SSP4 | C20: =[1]未来产量!E418 -> 650.68569
A21: =[1]未来产量!A450 -> 2027 | B21: =[1]未来产量!B450 -> SSP5 | C21: =[1]未来产量!E450 -> 654.84138
A22: =[1]未来产量!A482 -> 2028 | B22: =[1]未来产量!B482 -> SSP1 | C22: =[1]未来产量!E482 -> 649.49916
A23: =[1]未来产量!A514 -> 2028 | B23: =[1]未来产量!B514 -> SSP2 | C23: =[1]未来产量!E514 -> 658.07411
A24: =[1]未来产量!A546 -> 2028 | B24: =[1]未来产量!B546 -> SSP3 | C24: =[1]未来产量!E546 -> 662.63584
A25: =[1]未来产量!A578 -> 2028 | B25: =[1]未来产量!B578 -> SSP4 | C25: =[1]未来产量!E578 -> 650.85454
A26: =[1]未来产量!A610 -> 2028 | B26: =[1]未来产量!B610 -> SSP5 | C26: =[1]未来产量!E610 -> 657.08806
A27: =[1]未来产量!A642 -> 2029 | B27: =[1]未来产量!B642 -> SSP1 | C27: =[1]未来产量!E642 -> 649.21621
A28: =[1]未来产量!A674 -> 2029 | B28: =[1]未来产量!B674 -> SSP2 | C28: =[1]未来产量!E674 -> 660.64948
A29: =[1]未来产量!A706 -> 2029 | B29: =[1]未来产量!B706 -> SSP3 | C29: =[1]未来产量!E706 -> 666.73179
A30: =[1]未来产量!A738 -> 2029 | B30: =[1]未来产量!B738 -> SSP4 | C30: =[1]未来产量!E738 -> 651.02339
A31: =[1]未来产量!A770 -> 2029 | B31: =[1]未来产量!B770 -> SSP5 | C31: =[1]未来产量!E770 -> 659.33475
A32: =[1]未来产量!A802 -> 2030 | B32: =[1]未来产量!B802 -> SSP1 | C32: =[1]未来产量!E802 -> 648.93327
A33: =[1]未来产量!A834 -> 2030 | B33: =[1]未来产量!B834 -> SSP2 | C33: =[1]未来产量!E834 -> 663.22486
A34: =[1]未来产量!A866 -> 2030 | B34: =[1]未来产量!B866 -> SSP3 | C34: =[1]未来产量!E866 -> 670.82774
A35: =[1]未来产量!A898 -> 2030 | B35: =[1]未来产量!B898 -> SSP4 | C35: =[1]未来产量!E898 -> 651.19223
A36: =[1]未来产量!A930 -> 2030 | B36: =[1]未来产量!B930 -> SSP5 | C36: =[1]未来产量!E930 -> 661.58144
A37: =[1]未来产量!A962 -> 2031 | B37: =[1]未来产量!B962 -> SSP1 | C37: =[1]未来产量!E962 -> 648.65032
A38: =[1]未来产量!A994 -> 2031 | B38: =[1]未来产量!B994 -> SSP2 | C38: =[1]未来产量!E994 -> 665.80023
A39: =[1]未来产量!A1026 -> 2031 | B39: =[1]未来产量!B1026 -> SSP3 | C39: =[1]未来产量!E1026 -> 674.92368
A40: =[1]未来产量!A1058 -> 2031 | B40: =[1]未来产量!B1058 -> SSP4 | C40: =[1]未来产量!E1058 -> 651.36108
...
